Workbook

Sheet Investor Summary
B4: CAPEX Assumptions | D4: M$ | F4: Timing | G4: Method | H4: Notes | J4: T5 Share | K4: JV (Proposed) | N4: Tangible | O4: Intangible
B5: 4.01 | C5: Extraction & Reinjection Field | D5: 65.9 | F5: 2025 | G5: AFE | H5: (1) | J5: =D5 -> 65.9 | M5: 0.3 | N5: =M5*D5 -> 19.77 | O5: =D5-N5 -> 46.13
B6: 4.02 | C6: Interconnecting lines | D6: 17.6 | F6: 2026 | G6: BM | H6: (3) | J6: =D6 -> 17.6 | M6: 0.9 | N6: =M6*D6 -> 15.84 | O6: =D6-N6 -> 1.76
B7: 4.03 | C7: Brine Treatment | D7: 38.39088 | F7: 2026 | G7: Budget | H7: (2) | J7: =0.4*D7 -> 15.356352 | K7: =0.6*D7 -> 23.034528 | M7: 0.8 | N7: =M7*D7 -> 30.712704 | O7: =D7-N7 -> 7.678176
B8: 4.04 | C8: DLE | D8: 84.908384 | F8: 2026 | G8: Budget | H8: (2) | K8: =D8 -> 84.908384 | M8: 0.8 | N8: =M8*D8 -> 67.926707 | O8: =D8-N8 -> 16.981677
B9: 4.05 | C9: Purification & Concentration | D9: 30.712704 | F9: 2026 | G9: Budget | H9: (2) | K9: =D9 -> 30.712704 | M9: 0.8 | N9: =M9*D9 -> 24.570163 | O9: =D9-N9 -> 6.1425408
B10: 4.06 | C10: Lithium Conversion | D10: 26.976 | F10: 2027 | G10: Budget | H10: (2) | K10: =D10 -> 26.976 | M10: 0.8 | N10: =M10*D10 -> 21.5808 | O10: =D10-N10 -> 5.3952
B11: 4.07 | C11: Chemical Storage, Handling & Utilities | D11: 22.336512 | F11: 2026 | G11: BM | H11: (4) | J11: =D11 -> 22.336512 | M11: 0.9 | N11: =M11*D11 -> 20.102861 | O11: =D11-N11 -> 2.2336512
B12: 4.08 | C12: Geothermal | D12: 18 | F12: 2027 | G12: Budget | H12: (6) | J12: =D12 -> 18 | M12: 0.8 | N12: =M12*D12 -> 14.4 | O12: =D12-N12 -> 3.6
B13: 4.09 | C13: Infrastructure / Site works | D13: 9.6 | F13: 2026 | G13: Placeholder | J13: =D13 -> 9.6 | M13: 0.9 | N13: =M13*D13 -> 8.64 | O13: =D13-N13 -> 0.96
B14: 4.1 | C14: Project Implementation | D14: 15 | F14: 2026 | G14: Placeholder | H14: (5) | J14: =D14 -> 15 | M14: 0 | N14: =M14*D14 -> 0 | O14: =D14-N14 -> 15
B15: 4.11 | C15: Land Acquisition | D15: 5 | F15: 2025 | G15: Placeholder | J15: =D15 -> 5 | M15: 1 | N15: =M15*D15 -> 5 | O15: =D15-N15 -> 0
B17: Total | D17: =SUM(D5:D15) -> 334.42448 | J17: =SUM(J5:J15) -> 168.79286 | K17: =SUM(K5:K15) -> 165.63162 | N17: =SUM(N5:N15)/D17 -> 0.68339266 | O17: =SUM(O5:O15)/D17 -> 0.31660734
B18: Total (rounded ) represented in Investor Model | D18: =335 -> 335 | J18: 170
B20: Notes:
B21: (1) 08.2025 Blondie Lady #1 Approved AFE, includes contingency (see 4.01) - scaled to 8 producers and 4 injectors
B22: (2) 09.22.25 budgetary conversations with Reclaim Lithium for 4kta plant, scaled to 8 well program
B23: (3) Benchmarked from previous pipeline work
B24: (4) Benchmarked from SLI DFS as placeholder
B25: (5) Placeholder for all owners cost pre-revenue
B26: (6) 10.14.25 Proposal from Turboden

Sheet 4.01 CAPEX List
B2: 4.00 - CAPEX List | S2: TOC
B4: CAPEX List | R4: =SUM(Q8,Q28,Q30,Q60:S64) -> 3.3440012e+08
B6: Equipment Name / Description (A) | H6: Units | I6: Number of Units (B) | M6: Cost Per Unit (C) | Q6: Total Cost (D)
B8: Extraction & Reinjection Field | Q8: =Q9+Q18 -> 65900123
C9: Production Well | H9: ea. | I9: 8 | M9: =SUM(Q10:S17) -> 5325010.2 | Q9: =I9*M9 -> 42600082
D10: Surface Casing | H10: feet | I10: 1500 | M10: =Q10/I10 -> 41.838883 | Q10: 62758.325
D11: Intermediate Casing | H11: feet | I11: 11250 | M11: =Q11/I11 -> 52.331222 | Q11: 588726.25
D12: Wellhead Equipment | H12: ea. | I12: 1 | M12: =Q12/I12 -> 21350 | Q12: 21350
D13: Well Head | H13: ea. | I13: 1 | J13: 1 | M13: =Q13/I13 -> 181475 | Q13: 181475
D14: Tubing | H14: feet | I14: 11050 | M14: =Q14/I14 -> 24.01875 | Q14: 265407.19
D15: ESP | H15: ea. | I15: 1 | J15: 1 | M15: =Q15/I15 -> 414723.75 | Q15: 414723.75
D16: Intangible Drilling Costs | H16: ea. | I16: 1 | J16: 1 | M16: =Q16/I16 -> 3559350 | Q16: 3559350
D17: Intangible Completion Costs | H17: ea. | I17: 1 | J17: 1 | M17: =Q17/I17 -> 231219.7 | Q17: 231219.7
C18: Reinjection Well | H18: ea. | I18: 4 | M18: =SUM(Q19:S27) -> 5825010.2 | Q18: =I18*M18 -> 23300041
D19: Surface Casing | H19: feet | I19: 1500 | M19: =Q19/I19 -> 41.838883 | Q19: 62758.325
D20: Intermediate Casing | H20: feet | I20: 11250 | M20: =Q20/I20 -> 52.331222 | Q20: 588726.25
D21: Wellhead Equipment | H21: ea. | I21: 1 | M21: =Q21/I21 -> 21350 | Q21: 21350
D22: Well Head | H22: ea. | I22: 1 | J22: 1 | M22: =Q22/I22 -> 181475 | Q22: 181475
D23: Tubing | H23: feet | I23: 11050 | M23: =Q23/I23 -> 24.01875 | Q23: 265407.19
D24: ESP | H24: ea. | I24: 1 | J24: 1 | M24: =Q24/I24 -> 414723.75 | Q24: 414723.75
D25: Intangible Drilling Costs | H25: ea. | I25: 1 | J25: 1 | M25: =Q25/I25 -> 3559350 | Q25: 3559350
D26: Intangible Completion Costs | H26: ea. | I26: 1 | J26: 1 | M26: =Q26/I26 -> 231219.7 | Q26: 231219.7
D27: Reinjection facilities | H27: ea. | I27: 1 | J27: 1 | M27: =Q27/I27 -> 500000 | Q27: 500000
B28: Interconnecting Lines | Q28: =Q29+Q38 -> 17600000
C29: Pipelines & Connections | H29: miles | I29: 8 | M29: 2200000 | Q29: =I29*M29 -> 17600000
B30: Brine Processing | Q30: =Q31+Q40+Q50+Q53 -> 181000000
C31: Brine Treatment | H31: ea. | I31: 8 | M31: 4800000 | Q31: =I31*M31 -> 38400000
D32: H2S Scrubber
D33: Feed Tank
D34: Organics Removal
D35: Clarifier
D36: Post Clarifier water tank
D37: Media filter
D38: Ultrafiltration system
D39: Solids Frac Tank
C40: DLE Processing | H40: ea. | I40: 1 | M40: 84900000 | Q40: =I40*M40 -> 84900000
D41: RO System
D42: Brine Feed Storage
D43: Spent Brine Storage
D44: Make up water Storage
...

Sheet JETI Program - CAPEX
B2: Capital Investment (Detailed budget by year and investment type) | F2: Total | G2: T5 Share
B3: Land and Property, including Upgrades | F3: ='Investor Summary'!D15 -> 5 | G3: =F3 -> 5
B4: Includes acquisition, lease, or improvement of land and existing structures. Ex: Purchase of land parcels
B5: Infrastructure | F5: ='Investor Summary'!D6+'Investor Summary'!D13 -> 27.2 | G5: =F5 -> 27.2
B6: Includes foundational systems and utilities that support the site. Ex: Road construction | H6: // Includes 4.02 and 4.09 from Investor Summary
B7: Building | F7: =0.05*SUM('Investor Summary'!D5,'Investor Summary'!D7:D11,'Investor Summary'!D12) -> 14.361224 | G7: =0.05*SUM('Investor Summary'!J5,'Investor Summary'!J7:J11,'Investor Summary'!J12) -> 6.0796432
B8: Includes construction or renovation of physical structures. Ex: Maintenance building construction | H8: // Assumed 5% of Technical Assets and Machinery
B9: Technical Assets and Machinery | F9: =0.7*SUM('Investor Summary'!D5,'Investor Summary'!D7:D11,'Investor Summary'!D12) -> 201.05714 | G9: =0.7*SUM('Investor Summary'!J5,'Investor Summary'!J7:J11,'Investor Summary'!J12) -> 85.115005
B10: Includes equipment and systems necessary for operations. Ex: Geothermal drilling rig | H10: // Includes 70% of 4.01, 4.03, 4.04, 4.05, 4.06, 4.07, 4.08
B11: Indirect Costs | F11: =0.25*SUM('Investor Summary'!D5,'Investor Summary'!D7:D11,'Investor Summary'!D12)+'Investor Summary'!D14 -> 86.80612 | G11: =0.25*SUM('Investor Summary'!J5,'Investor Summary'!J7:J11,'Investor Summary'!J12)+'Investor Summary'!J14 -> 45.398216
B12: Includes on-tangible or support-related expenses tied to the project. Ex: Engineering consulting services | H12: // Assumed 25% of Technical Assets and Machinery + 4.10
B14: Total | F14: =SUM(F3:F12) -> 334.42448 | G14: =SUM(G3:G12) -> 168.79286
B16: Capital Investment Questions
B17: Other than the project, please provide the total annual capital investment budget for the facility for the next 5 years, if available.
B18: Will any of the proposed required investment be leased under a capitalized lease?
